23:41:44,627 urllib3.connection ERROR Certificate did not match expected hostname: qm.leichtbewaff.net. Certificate: {'subject': ((('commonName', 'leichtbewaff.net'),),), 'issuer': ((('countryName', 'GB'),), (('stateOrProvinceName', 'Greater Manchester'),), (('localityName', 'Salford'),), (('organizationName', 'Sectigo Limited'),), (('commonName', 'Sectigo RSA Domain Validation Secure Server CA'),)), 'version': 3, 'serialNumber': '44519CF262D06CB3E7EBE44EC7E93A13', 'notBefore': 'Jul  6 00:00:00 2019 GMT', 'notAfter': 'Oct  4 23:59:59 2019 GMT', 'subjectAltName': (('DNS', 'leichtbewaff.net'), ('DNS', 'www.leichtbewaff.net')), 'OCSP': ('http://ocsp.sectigo.com',), 'caIssuers': ('http://crt.sectigo.com/SectigoRSADomainValidationSecureServerCA.crt',)}
23:41:44,628 root ERROR 
Traceback (most recent call last):
  File "C:\Program Files (x86)\Python37-32\lib\site-packages\urllib3\connectionpool.py", line 603, in urlopen
    chunked=chunked)
  File "C:\Program Files (x86)\Python37-32\lib\site-packages\urllib3\connectionpool.py", line 344, in _make_request
    self._validate_conn(conn)
  File "C:\Program Files (x86)\Python37-32\lib\site-packages\urllib3\connectionpool.py", line 843, in _validate_conn
    conn.connect()
  File "C:\Program Files (x86)\Python37-32\lib\site-packages\urllib3\connection.py", line 390, in connect
    _match_hostname(cert, self.assert_hostname or server_hostname)
  File "C:\Program Files (x86)\Python37-32\lib\site-packages\urllib3\connection.py", line 400, in _match_hostname
    match_hostname(cert, asserted_hostname)
  File "C:\Program Files (x86)\Python37-32\lib\ssl.py", line 334, in match_hostname
    % (hostname, ', '.join(map(repr, dnsnames))))
ssl.SSLCertVerificationError: ("hostname 'qm.leichtbewaff.net' doesn't match either of 'leichtbewaff.net', 'www.leichtbewaff.net'",)

During handling of the above exception, another exception occurred:

Traceback (most recent call last):
  File "C:\Program Files (x86)\Python37-32\lib\site-packages\requests\adapters.py", line 449, in send
    timeout=timeout
  File "C:\Program Files (x86)\Python37-32\lib\site-packages\urllib3\connectionpool.py", line 641, in urlopen
    _stacktrace=sys.exc_info()[2])
  File "C:\Program Files (x86)\Python37-32\lib\site-packages\urllib3\util\retry.py", line 399, in increment
    raise MaxRetryError(_pool, url, error or ResponseError(cause))
urllib3.exceptions.MaxRetryError: HTTPSConnectionPool(host='qm.leichtbewaff.net', port=443): Max retries exceeded with url: /soap/python/import (Caused by SSLError(SSLCertVerificationError("hostname 'qm.leichtbewaff.net' doesn't match either of 'leichtbewaff.net', 'www.leichtbewaff.net'")))

During handling of the above exception, another exception occurred:

Traceback (most recent call last):
  File "c:\xampp\htdocs\qm\python\sync.py", line 35, in <module>
    r = requests.post("https://qm.leichtbewaff.net/soap/python/import", data={'xml': response})
  File "C:\Program Files (x86)\Python37-32\lib\site-packages\requests\api.py", line 116, in post
    return request('post', url, data=data, json=json, **kwargs)
  File "C:\Program Files (x86)\Python37-32\lib\site-packages\requests\api.py", line 60, in request
    return session.request(method=method, url=url, **kwargs)
  File "C:\Program Files (x86)\Python37-32\lib\site-packages\requests\sessions.py", line 533, in request
    resp = self.send(prep, **send_kwargs)
  File "C:\Program Files (x86)\Python37-32\lib\site-packages\requests\sessions.py", line 646, in send
    r = adapter.send(request, **kwargs)
  File "C:\Program Files (x86)\Python37-32\lib\site-packages\requests\adapters.py", line 514, in send
    raise SSLError(e, request=request)
requests.exceptions.SSLError: HTTPSConnectionPool(host='qm.leichtbewaff.net', port=443): Max retries exceeded with url: /soap/python/import (Caused by SSLError(SSLCertVerificationError("hostname 'qm.leichtbewaff.net' doesn't match either of 'leichtbewaff.net', 'www.leichtbewaff.net'")))
